Train Epoch: 1 [0/2608 (0%)]	Loss: 0.718989
Train Epoch: 1 [800/2608 (31%)]	Loss: 0.350208
Train Epoch: 1 [1600/2608 (61%)]	Loss: 0.188693
Train Epoch: 1 [2400/2608 (92%)]	Loss: 0.138056
Average loss : 0.34898652508854866
Train Epoch: 2 [0/2608 (0%)]	Loss: 0.216929
Train Epoch: 2 [800/2608 (31%)]	Loss: 0.103894
Train Epoch: 2 [1600/2608 (61%)]	Loss: 0.009390
Train Epoch: 2 [2400/2608 (92%)]	Loss: 0.022307
Average loss : 0.08813040144741535
Train Epoch: 3 [0/2608 (0%)]	Loss: 0.256427
Train Epoch: 3 [800/2608 (31%)]	Loss: 0.116691
Train Epoch: 3 [1600/2608 (61%)]	Loss: 0.137619
Train Epoch: 3 [2400/2608 (92%)]	Loss: 0.024126
Average loss : 0.13371570501476526
Train Epoch: 4 [0/2608 (0%)]	Loss: 0.069736
Train Epoch: 4 [800/2608 (31%)]	Loss: 0.288695
Train Epoch: 4 [1600/2608 (61%)]	Loss: 0.070213
Train Epoch: 4 [2400/2608 (92%)]	Loss: 0.043489
Average loss : 0.11803323682397604
model sent successfully!
Train Epoch: 1 [0/2608 (0%)]	Loss: 0.070151
Train Epoch: 1 [800/2608 (31%)]	Loss: 0.291490
Train Epoch: 1 [1600/2608 (61%)]	Loss: 0.148820
Train Epoch: 1 [2400/2608 (92%)]	Loss: 0.102024
Average loss : 0.15312134101986885
Train Epoch: 2 [0/2608 (0%)]	Loss: 0.210996
Train Epoch: 2 [800/2608 (31%)]	Loss: 0.002574
Train Epoch: 2 [1600/2608 (61%)]	Loss: 0.074250
Train Epoch: 2 [2400/2608 (92%)]	Loss: 0.169340
Average loss : 0.11428998038172722
Train Epoch: 3 [0/2608 (0%)]	Loss: 0.203434
Train Epoch: 3 [800/2608 (31%)]	Loss: 0.001318
Train Epoch: 3 [1600/2608 (61%)]	Loss: 0.038246
Train Epoch: 3 [2400/2608 (92%)]	Loss: 0.118941
Average loss : 0.09048473555594683
Train Epoch: 4 [0/2608 (0%)]	Loss: 0.010660
Train Epoch: 4 [800/2608 (31%)]	Loss: 0.072473
Train Epoch: 4 [1600/2608 (61%)]	Loss: 0.032606
Train Epoch: 4 [2400/2608 (92%)]	Loss: 0.198204
Average loss : 0.07848596293479204
model sent successfully!
Waiting for aggregation...
Waiting for aggregation...
Train Epoch: 1 [0/2608 (0%)]	Loss: 0.005320
Train Epoch: 1 [800/2608 (31%)]	Loss: 0.027253
Train Epoch: 1 [1600/2608 (61%)]	Loss: 0.121516
Train Epoch: 1 [2400/2608 (92%)]	Loss: 0.073237
Average loss : 0.05683159036561847
Train Epoch: 2 [0/2608 (0%)]	Loss: 0.051862
Train Epoch: 2 [800/2608 (31%)]	Loss: 0.005444
Train Epoch: 2 [1600/2608 (61%)]	Loss: 0.146464
Train Epoch: 2 [2400/2608 (92%)]	Loss: 0.005723
Average loss : 0.052373132668435574
Train Epoch: 3 [0/2608 (0%)]	Loss: 0.008979
Train Epoch: 3 [800/2608 (31%)]	Loss: 0.002092
Train Epoch: 3 [1600/2608 (61%)]	Loss: 0.003774
Train Epoch: 3 [2400/2608 (92%)]	Loss: 0.097344
Average loss : 0.028047416359186172
Train Epoch: 4 [0/2608 (0%)]	Loss: 0.005280
Train Epoch: 4 [800/2608 (31%)]	Loss: 0.004607
Train Epoch: 4 [1600/2608 (61%)]	Loss: 0.002543
Train Epoch: 4 [2400/2608 (92%)]	Loss: 0.002636
Average loss : 0.0037665069103240967
model sent successfully!
Waiting for aggregation...
Waiting for aggregation...
Waiting for aggregation...
Waiting for aggregation...
Traceback (most recent call last):
  File "/home/nikamanth/.local/lib/python3.7/site-packages/urllib3/connection.py", line 160, in _new_conn
    (self._dns_host, self.port), self.timeout, **extra_kw
  File "/home/nikamanth/.local/lib/python3.7/site-packages/urllib3/util/connection.py", line 84, in create_connection
    raise err
  File "/home/nikamanth/.local/lib/python3.7/site-packages/urllib3/util/connection.py", line 74, in create_connection
    sock.connect(sa)
ConnectionRefusedError: [Errno 111] Connection refused

During handling of the above exception, another exception occurred:

Traceback (most recent call last):
  File "/home/nikamanth/.local/lib/python3.7/site-packages/urllib3/connectionpool.py", line 677, in urlopen
    chunked=chunked,
  File "/home/nikamanth/.local/lib/python3.7/site-packages/urllib3/connectionpool.py", line 392, in _make_request
    conn.request(method, url, **httplib_request_kw)
  File "/home/nikamanth/anaconda3/envs/torch/lib/python3.7/http/client.py", line 1277, in request
    self._send_request(method, url, body, headers, encode_chunked)
  File "/home/nikamanth/anaconda3/envs/torch/lib/python3.7/http/client.py", line 1323, in _send_request
    self.endheaders(body, encode_chunked=encode_chunked)
  File "/home/nikamanth/anaconda3/envs/torch/lib/python3.7/http/client.py", line 1272, in endheaders
    self._send_output(message_body, encode_chunked=encode_chunked)
  File "/home/nikamanth/anaconda3/envs/torch/lib/python3.7/http/client.py", line 1032, in _send_output
    self.send(msg)
  File "/home/nikamanth/anaconda3/envs/torch/lib/python3.7/http/client.py", line 972, in send
    self.connect()
  File "/home/nikamanth/.local/lib/python3.7/site-packages/urllib3/connection.py", line 187, in connect
    conn = self._new_conn()
  File "/home/nikamanth/.local/lib/python3.7/site-packages/urllib3/connection.py", line 172, in _new_conn
    self, "Failed to establish a new connection: %s" % e
urllib3.exceptions.NewConnectionError: <urllib3.connection.HTTPConnection object at 0x7f08cc5f4790>: Failed to establish a new connection: [Errno 111] Connection refused

During handling of the above exception, another exception occurred:

Traceback (most recent call last):
  File "/home/nikamanth/anaconda3/envs/torch/lib/python3.7/site-packages/requests/adapters.py", line 449, in send
    timeout=timeout
  File "/home/nikamanth/.local/lib/python3.7/site-packages/urllib3/connectionpool.py", line 725, in urlopen
    method, url, error=e, _pool=self, _stacktrace=sys.exc_info()[2]
  File "/home/nikamanth/.local/lib/python3.7/site-packages/urllib3/util/retry.py", line 439, in increment
    raise MaxRetryError(_pool, url, error or ResponseError(cause))
urllib3.exceptions.MaxRetryError: HTTPConnectionPool(host='localhost', port=5000): Max retries exceeded with url: /checkphase (Caused by NewConnectionError('<urllib3.connection.HTTPConnection object at 0x7f08cc5f4790>: Failed to establish a new connection: [Errno 111] Connection refused'))

During handling of the above exception, another exception occurred:

Traceback (most recent call last):
  File "run.py", line 34, in <module>
    getModel(agg_url, model_path, local_agg_epoch)
  File "/home/nikamanth/Documents/fyp/src/client/httpcalls.py", line 11, in getModel
    json={"local_agg_epoch": local_agg_epoch} \
  File "/home/nikamanth/anaconda3/envs/torch/lib/python3.7/site-packages/requests/api.py", line 116, in post
    return request('post', url, data=data, json=json, **kwargs)
  File "/home/nikamanth/anaconda3/envs/torch/lib/python3.7/site-packages/requests/api.py", line 60, in request
    return session.request(method=method, url=url, **kwargs)
  File "/home/nikamanth/anaconda3/envs/torch/lib/python3.7/site-packages/requests/sessions.py", line 533, in request
    resp = self.send(prep, **send_kwargs)
  File "/home/nikamanth/anaconda3/envs/torch/lib/python3.7/site-packages/requests/sessions.py", line 646, in send
    r = adapter.send(request, **kwargs)
  File "/home/nikamanth/anaconda3/envs/torch/lib/python3.7/site-packages/requests/adapters.py", line 516, in send
    raise ConnectionError(e, request=request)
requests.exceptions.ConnectionError: HTTPConnectionPool(host='localhost', port=5000): Max retries exceeded with url: /checkphase (Caused by NewConnectionError('<urllib3.connection.HTTPConnection object at 0x7f08cc5f4790>: Failed to establish a new connection: [Errno 111] Connection refused'))
